<mujoco model="ant">
  <compiler angle="radian" coordinate="local" inertiafromgeom="true"/>
  <option integrator="RK4" timestep="0.01"/>
  <custom>
    <numeric data="0.0 0.0 0.08 1.0 0.0 0.0 0.0 0.0 0.0 1.0 0.0 0.0 -1.0 0.0 0.0 -1.0 0.0 0.0 1.0" name="init_qpos"/>
  </custom>
  <default>
    <joint armature="1" damping="1" limited="true"/>
    <geom conaffinity="0" condim="3" density="5.0" friction="1 0.5 0.5" margin="0.01" rgba="0.8 0.6 0.4 1"/>
  </default>
  <asset>
    <texture builtin="gradient" height="100" rgb1="1 1 1" rgb2="0 0 0" type="skybox" width="100"/>
    <texture builtin="flat" height="1278" mark="cross" markrgb="1 1 1" name="texgeom" random="0.01" rgb1="0.8 0.6 0.4" rgb2="0.8 0.6 0.4" type="cube" width="127"/>
    <texture builtin="checker" height="100" name="texplane" rgb1="0 0 0" rgb2="0.8 0.8 0.8" type="2d" width="100"/>
    <material name="MatPlane" reflectance="0.5" shininess="1" specular="1" texrepeat="60 60" texture="texplane"/>
    <material name="geom" texture="texgeom" texuniform="true"/>
  </asset>
  <worldbody>
    <light cutoff="100" diffuse="1 1 1" dir="-0 0 -1.3" directional="true" exponent="1" pos="0 0 1.3" specular=".1 .1 .1"/>
    <geom conaffinity="1" condim="3" material="MatPlane" name="floor" pos="0 0 0" rgba="0.8 0.9 0.8 1" size="40 40 40" type="plane"/>
    <body name="torso" pos="0 0 0.08">
      <camera name="track" mode="trackcom" pos="0 0.078 0.03" xyaxes="1 0 0 0 0 1"/>
      <geom name="torso_geom" pos="0 0 0" size="0.077 0.078 0.03" type="box"/>
      <joint armature="0" damping="0" limited="false" margin="0.01" name="root" pos="0 0 0" type="free"/>
      <site name='imu' size='0.008' pos='0.0 0.0 0.04'/>
      <body name="front_left_leg" pos="0 0 0">
        <geom fromto="0.0 0.0 0.0 0.075 0.075 0.0" name="leg_1_geom" size="0.020" type="capsule"/>
        <body name="femur_1" pos="0.075 0.075 0">
          <joint axis="0 0 1" name="hip_1" pos="0.0 0.0 0.0" range="-1.0471 1.0471" type="hinge"/>
          <geom fromto="0.0 0.0 0.0 0.027 0.027 0.0" name="femur_1_geom" size="0.020" type="capsule"/>
          <body name="tibia_1" pos="0.027 0.027 0">
            <joint axis="-1 1 0" name="knee_1" pos="0.0 0.0 0.0" range="-1.0471 1.0471" type="hinge"/>
            <geom fromto="0.0 0.0 0.0 0.025 0.025 0.0" name="tibia_1_geom" size="0.008" type="capsule"/>
            <body name="tarsus_1" pos="0.025 0.025 0.0">
              <joint axis="-1 1 0" name="ankle_1" pos="0.0 0.0 0.0" range="1.2217 2.2094" type="hinge"/>
              <geom fromto="0.0 0.0 0.0 0.057 0.057 0.0" name="tarsus_1_geom" size="0.012" type="capsule"/>
            </body>
          </body>
        </body>
      </body>
      <body name="front_right_leg" pos="0 0 0">
        <geom fromto="0.0 0.0 0.0 -0.075 0.075 0.0" name="leg_2_geom" size="0.020" type="capsule"/>
        <body name="femur_2" pos="-0.075 0.075 0">
          <joint axis="0 0 1" name="hip_2" pos="0.0 0.0 0.0" range="-1.0471 1.0471" type="hinge"/>
          <geom fromto="0.0 0.0 0.0 -0.027 0.027 0.0" name="femur_2_geom" size="0.020" type="capsule"/>
          <body name="tibia_2" pos="-0.027 0.027 0">
            <joint axis="1 1 0" name="knee_2" pos="0.0 0.0 0.0" range="-1.0471 1.0471" type="hinge"/>
            <geom fromto="0.0 0.0 0.0 -0.025 0.025 0.0" name="tibia_2_geom" size="0.008" type="capsule"/>
            <body name="tarsus_2" pos="-0.025 0.025 00">
              <joint axis="1 1 0" name="ankle_2" pos="0.0 0.0 0.0" range="-2.2094 -1.2217" type="hinge"/>
              <geom fromto="0.0 0.0 0.0 -0.057 0.057 0.0" name="tarsus_2_geom" size="0.012" type="capsule"/>
            </body>
          </body>
        </body>
      </body>
      <body name="back_right_leg" pos="0 0 0">
        <geom fromto="0.0 0.0 0.0 -0.075 -0.075 0.0" name="leg_3_geom" size="0.020" type="capsule"/>
        <body name="femur_3" pos="-0.075 -0.075 0">
          <joint axis="0 0 1" name="hip_3" pos="0.0 0.0 0.0" range="-1.0471 1.0471" type="hinge"/>
          <geom fromto="0.0 0.0 0.0 -0.027 -0.027 0.0" name="femur_3_geom" size="0.020" type="capsule"/>
          <body name="tibia_3" pos="-0.027 -0.027 0">
            <joint axis="-1 1 0" name="knee_3" pos="0.0 0.0 0.0" range="-1.0471 1.0471" type="hinge"/>
            <geom fromto="0.0 0.0 0.0 -0.025 -0.025 0.0" name="tibia_3_geom" size="0.008" type="capsule"/>
            <body name="tarsus_3" pos="-0.025 -0.025 0.0">
              <joint axis="-1 1 0" name="ankle_3" pos="0.0 0.0 0.0" range="-2.2094 -1.2217" type="hinge"/>
              <geom fromto="0.0 0.0 0.0 -0.057 -0.057 0.0" name="tarsus_3_geom" size="0.012" type="capsule"/>
            </body>
          </body>
        </body>
      </body>
      <body name="back_left_leg" pos="0 0 0">
        <geom fromto="0.0 0.0 0.0 0.075 -0.075 0.0" name="leg_4_geom" size="0.020" type="capsule"/>
        <body name="femur_4" pos="0.075 -0.075 0">
          <joint axis="0 0 1" name="hip_4" pos="0.0 0.0 0.0" range="-1.0471 1.0471" type="hinge"/>
          <geom fromto="0.0 0.0 0.0 0.027 -0.027 0.0" name="femur_4_geom" size="0.020" type="capsule"/>
          <body name="tibia_4" pos="0.027 -0.027 0">
            <joint axis="1 1 0" name="knee_4" pos="0.0 0.0 0.0" range="-1.0471 1.0471" type="hinge"/>
            <geom fromto="0.0 0.0 0.0 0.025 -0.025 0.0" name="tibia_4_geom" size="0.008" type="capsule"/>
            <body name="tarsus_4" pos="0.025 -0.025 0.0">
              <joint axis="1 1 0" name="ankle_4" pos="0.0 0.0 0.0" range="1.2217 2.2094" type="hinge"/>
              <geom fromto="0.0 0.0 0.0 0.057 -0.057 0.0" name="tarsus_geom" size="0.012" type="capsule"/>
            </body>
          </body>
        </body>
      </body>
    </body>
  </worldbody>
  <sensor>
    <gyro name='gyro' site='imu' noise='5e-4' cutoff='34.9'/>
    <accelerometer name='acc' site='imu' noise='1e-2' cutoff='157'/>
  </sensor>
  <actuator>
    <position ctrllimited="true" ctrlrange="-2 2" joint="hip_1" gear="1" kp="60"/>
    <position ctrllimited="true" ctrlrange="-2 2" joint="knee_1" gear="1" kp="60"/>
    <position ctrllimited="true" ctrlrange="-2 2" joint="ankle_1" gear="1" kp="60"/>
    <position ctrllimited="true" ctrlrange="-2 1" joint="hip_2" gear="1" kp="60"/>
    <position ctrllimited="true" ctrlrange="-2 2" joint="knee_2" gear="1" kp="60"/>
    <position ctrllimited="true" ctrlrange="-2 2" joint="ankle_2" gear="1" kp="60"/>
    <position ctrllimited="true" ctrlrange="-2 2" joint="hip_3" gear="1" kp="60"/>
    <position ctrllimited="true" ctrlrange="-2 2" joint="knee_3" gear="1" kp="60"/>
    <position ctrllimited="true" ctrlrange="-2 2" joint="ankle_3" gear="1" kp="60"/>
    <position ctrllimited="true" ctrlrange="-2 2" joint="hip_4" gear="1" kp="60"/>
    <position ctrllimited="true" ctrlrange="-2 2" joint="knee_4" gear="1" kp="60"/>
    <position ctrllimited="true" ctrlrange="-2 2" joint="ankle_4" gear="1" kp="60"/>

  </actuator>
</mujoco>
